Workbook

Sheet Cai dat
A1: CAI DAT & CHU THICH (FTMO 10K)
A3: THAM SO CHINH
A4: So du tai khoan ($) | B4: 10000
A5: Risk thap (%) | B5: 0.005
A6: Risk cao (%) | B6: 0.01
A7: So lenh / thang | B7: 20
A8: Risk $ (thap) = B4*B5 | B8: =B4*B5 -> 50
A9: Risk $ (cao) = B4*B6 | B9: =B4*B6 -> 100
A11: GIA TRI 1.00 LOT (dung de tinh lot size)
A12: EURUSD ($/pip, 1pip=0.0001) | B12: 10 | C12: SL do bang pip
A13: GBPUSD ($/pip, 1pip=0.0001) | B13: 10 | C13: SL do bang pip
A14: XAUUSD ($ / 1.0 USD gia) | B14: 100 | C14: SL do bang USD gia (vd 5.0)
A15: NAS100 ($ / 1 point) | B15: 1 | C15: SL do bang point (index)
A17: CHU THICH
A18: O to vang + chu xanh = O NHAP LIEU (ban tu sua)
A19: Chu den = cong thuc tu dong tinh
A20: Doi so du / risk% o tren -> moi bang tu dong cap nhat

Sheet Lot Size
A1: BANG LOT SIZE - TK 10K FTMO
A2: Lot = Risk$ / (SL x gia tri 1 lot). Doi risk/so du tai sheet 'Cai dat'.
A4: EURUSD (SL tinh bang PIP)
A5: SL (pip) | B5: Lot @ Risk thap | C5: Lot @ Risk cao | D5: Rui ro $ (thap) | E5: Rui ro $ (cao)
A6: 10 | B6: =ROUND('Cai dat'!$B$8/(A6*'Cai dat'!$B$12),2) -> 0.5 | C6: =ROUND('Cai dat'!$B$9/(A6*'Cai dat'!$B$12),2) -> 1 | D6: ='Cai dat'!$B$8 -> 50 | E6: ='Cai dat'!$B$9 -> 100
A7: 15 | B7: =ROUND('Cai dat'!$B$8/(A7*'Cai dat'!$B$12),2) -> 0.33 | C7: =ROUND('Cai dat'!$B$9/(A7*'Cai dat'!$B$12),2) -> 0.67 | D7: ='Cai dat'!$B$8 -> 50 | E7: ='Cai dat'!$B$9 -> 100
A8: 20 | B8: =ROUND('Cai dat'!$B$8/(A8*'Cai dat'!$B$12),2) -> 0.25 | C8: =ROUND('Cai dat'!$B$9/(A8*'Cai dat'!$B$12),2) -> 0.5 | D8: ='Cai dat'!$B$8 -> 50 | E8: ='Cai dat'!$B$9 -> 100
A9: 25 | B9: =ROUND('Cai dat'!$B$8/(A9*'Cai dat'!$B$12),2) -> 0.2 | C9: =ROUND('Cai dat'!$B$9/(A9*'Cai dat'!$B$12),2) -> 0.4 | D9: ='Cai dat'!$B$8 -> 50 | E9: ='Cai dat'!$B$9 -> 100
A10: 30 | B10: =ROUND('Cai dat'!$B$8/(A10*'Cai dat'!$B$12),2) -> 0.17 | C10: =ROUND('Cai dat'!$B$9/(A10*'Cai dat'!$B$12),2) -> 0.33 | D10: ='Cai dat'!$B$8 -> 50 | E10: ='Cai dat'!$B$9 -> 100
A11: 40 | B11: =ROUND('Cai dat'!$B$8/(A11*'Cai dat'!$B$12),2) -> 0.13 | C11: =ROUND('Cai dat'!$B$9/(A11*'Cai dat'!$B$12),2) -> 0.25 | D11: ='Cai dat'!$B$8 -> 50 | E11: ='Cai dat'!$B$9 -> 100
A12: 50 | B12: =ROUND('Cai dat'!$B$8/(A12*'Cai dat'!$B$12),2) -> 0.1 | C12: =ROUND('Cai dat'!$B$9/(A12*'Cai dat'!$B$12),2) -> 0.2 | D12: ='Cai dat'!$B$8 -> 50 | E12: ='Cai dat'!$B$9 -> 100
A13: 75 | B13: =ROUND('Cai dat'!$B$8/(A13*'Cai dat'!$B$12),2) -> 0.07 | C13: =ROUND('Cai dat'!$B$9/(A13*'Cai dat'!$B$12),2) -> 0.13 | D13: ='Cai dat'!$B$8 -> 50 | E13: ='Cai dat'!$B$9 -> 100
A14: 100 | B14: =ROUND('Cai dat'!$B$8/(A14*'Cai dat'!$B$12),2) -> 0.05 | C14: =ROUND('Cai dat'!$B$9/(A14*'Cai dat'!$B$12),2) -> 0.1 | D14: ='Cai dat'!$B$8 -> 50 | E14: ='Cai dat'!$B$9 -> 100
A16: GBPUSD (SL tinh bang PIP)
A17: SL (pip) | B17: Lot @ Risk thap | C17: Lot @ Risk cao | D17: Rui ro $ (thap) | E17: Rui ro $ (cao)
A18: 10 | B18: =ROUND('Cai dat'!$B$8/(A18*'Cai dat'!$B$13),2) -> 0.5 | C18: =ROUND('Cai dat'!$B$9/(A18*'Cai dat'!$B$13),2) -> 1 | D18: ='Cai dat'!$B$8 -> 50 | E18: ='Cai dat'!$B$9 -> 100
A19: 15 | B19: =ROUND('Cai dat'!$B$8/(A19*'Cai dat'!$B$13),2) -> 0.33 | C19: =ROUND('Cai dat'!$B$9/(A19*'Cai dat'!$B$13),2) -> 0.67 | D19: ='Cai dat'!$B$8 -> 50 | E19: ='Cai dat'!$B$9 -> 100
A20: 20 | B20: =ROUND('Cai dat'!$B$8/(A20*'Cai dat'!$B$13),2) -> 0.25 | C20: =ROUND('Cai dat'!$B$9/(A20*'Cai dat'!$B$13),2) -> 0.5 | D20: ='Cai dat'!$B$8 -> 50 | E20: ='Cai dat'!$B$9 -> 100
A21: 25 | B21: =ROUND('Cai dat'!$B$8/(A21*'Cai dat'!$B$13),2) -> 0.2 | C21: =ROUND('Cai dat'!$B$9/(A21*'Cai dat'!$B$13),2) -> 0.4 | D21: ='Cai dat'!$B$8 -> 50 | E21: ='Cai dat'!$B$9 -> 100
A22: 30 | B22: =ROUND('Cai dat'!$B$8/(A22*'Cai dat'!$B$13),2) -> 0.17 | C22: =ROUND('Cai dat'!$B$9/(A22*'Cai dat'!$B$13),2) -> 0.33 | D22: ='Cai dat'!$B$8 -> 50 | E22: ='Cai dat'!$B$9 -> 100
A23: 40 | B23: =ROUND('Cai dat'!$B$8/(A23*'Cai dat'!$B$13),2) -> 0.13 | C23: =ROUND('Cai dat'!$B$9/(A23*'Cai dat'!$B$13),2) -> 0.25 | D23: ='Cai dat'!$B$8 -> 50 | E23: ='Cai dat'!$B$9 -> 100
A24: 50 | B24: =ROUND('Cai dat'!$B$8/(A24*'Cai dat'!$B$13),2) -> 0.1 | C24: =ROUND('Cai dat'!$B$9/(A24*'Cai dat'!$B$13),2) -> 0.2 | D24: ='Cai dat'!$B$8 -> 50 | E24: ='Cai dat'!$B$9 -> 100
A25: 75 | B25: =ROUND('Cai dat'!$B$8/(A25*'Cai dat'!$B$13),2) -> 0.07 | C25: =ROUND('Cai dat'!$B$9/(A25*'Cai dat'!$B$13),2) -> 0.13 | D25: ='Cai dat'!$B$8 -> 50 | E25: ='Cai dat'!$B$9 -> 100
A26: 100 | B26: =ROUND('Cai dat'!$B$8/(A26*'Cai dat'!$B$13),2) -> 0.05 | C26: =ROUND('Cai dat'!$B$9/(A26*'Cai dat'!$B$13),2) -> 0.1 | D26: ='Cai dat'!$B$8 -> 50 | E26: ='Cai dat'!$B$9 -> 100
A28: XAUUSD / GOLD (SL tinh bang USD gia)
A29: SL (USD) | B29: Lot @ Risk thap | C29: Lot @ Risk cao | D29: Rui ro $ (thap) | E29: Rui ro $ (cao)
A30: 2 | B30: =ROUND('Cai dat'!$B$8/(A30*'Cai dat'!$B$14),2) -> 0.25 | C30: =ROUND('Cai dat'!$B$9/(A30*'Cai dat'!$B$14),2) -> 0.5 | D30: ='Cai dat'!$B$8 -> 50 | E30: ='Cai dat'!$B$9 -> 100
A31: 3 | B31: =ROUND('Cai dat'!$B$8/(A31*'Cai dat'!$B$14),2) -> 0.17 | C31: =ROUND('Cai dat'!$B$9/(A31*'Cai dat'!$B$14),2) -> 0.33 | D31: ='Cai dat'!$B$8 -> 50 | E31: ='Cai dat'!$B$9 -> 100
A32: 5 | B32: =ROUND('Cai dat'!$B$8/(A32*'Cai dat'!$B$14),2) -> 0.1 | C32: =ROUND('Cai dat'!$B$9/(A32*'Cai dat'!$B$14),2) -> 0.2 | D32: ='Cai dat'!$B$8 -> 50 | E32: ='Cai dat'!$B$9 -> 100
A33: 7 | B33: =ROUND('Cai dat'!$B$8/(A33*'Cai dat'!$B$14),2) -> 0.07 | C33: =ROUND('Cai dat'!$B$9/(A33*'Cai dat'!$B$14),2) -> 0.14 | D33: ='Cai dat'!$B$8 -> 50 | E33: ='Cai dat'!$B$9 -> 100
A34: 10 | B34: =ROUND('Cai dat'!$B$8/(A34*'Cai dat'!$B$14),2) -> 0.05 | C34: =ROUND('Cai dat'!$B$9/(A34*'Cai dat'!$B$14),2) -> 0.1 | D34: ='Cai dat'!$B$8 -> 50 | E34: ='Cai dat'!$B$9 -> 100
A35: 15 | B35: =ROUND('Cai dat'!$B$8/(A35*'Cai dat'!$B$14),2) -> 0.03 | C35: =ROUND('Cai dat'!$B$9/(A35*'Cai dat'!$B$14),2) -> 0.07 | D35: ='Cai dat'!$B$8 -> 50 | E35: ='Cai dat'!$B$9 -> 100
A36: 20 | B36: =ROUND('Cai dat'!$B$8/(A36*'Cai dat'!$B$14),2) -> 0.03 | C36: =ROUND('Cai dat'!$B$9/(A36*'Cai dat'!$B$14),2) -> 0.05 | D36: ='Cai dat'!$B$8 -> 50 | E36: ='Cai dat'!$B$9 -> 100
A38: NAS100 (SL tinh bang POINT)
A39: SL (point) | B39: Lot @ Risk thap | C39: Lot @ Risk cao | D39: Rui ro $ (thap) | E39: Rui ro $ (cao)
A40: 20 | B40: =ROUND('Cai dat'!$B$8/(A40*'Cai dat'!$B$15),2) -> 2.5 | C40: =ROUND('Cai dat'!$B$9/(A40*'Cai dat'!$B$15),2) -> 5 | D40: ='Cai dat'!$B$8 -> 50 | E40: ='Cai dat'!$B$9 -> 100
A41: 30 | B41: =ROUND('Cai dat'!$B$8/(A41*'Cai dat'!$B$15),2) -> 1.67 | C41: =ROUND('Cai dat'!$B$9/(A41*'Cai dat'!$B$15),2) -> 3.33 | D41: ='Cai dat'!$B$8 -> 50 | E41: ='Cai dat'!$B$9 -> 100
A42: 50 | B42: =ROUND('Cai dat'!$B$8/(A42*'Cai dat'!$B$15),2) -> 1 | C42: =ROUND('Cai dat'!$B$9/(A42*'Cai dat'!$B$15),2) -> 2 | D42: ='Cai dat'!$B$8 -> 50 | E42: ='Cai dat'!$B$9 -> 100
A43: 75 | B43: =ROUND('Cai dat'!$B$8/(A43*'Cai dat'!$B$15),2) -> 0.67 | C43: =ROUND('Cai dat'!$B$9/(A43*'Cai dat'!$B$15),2) -> 1.33 | D43: ='Cai dat'!$B$8 -> 50 | E43: ='Cai dat'!$B$9 -> 100
A44: 100 | B44: =ROUND('Cai dat'!$B$8/(A44*'Cai dat'!$B$15),2) -> 0.5 | C44: =ROUND('Cai dat'!$B$9/(A44*'Cai dat'!$B$15),2) -> 1 | D44: ='Cai dat'!$B$8 -> 50 | E44: ='Cai dat'!$B$9 -> 100
...

Sheet Profit Expectancy
A1: MAY TINH LOI NHUAN theo WIN% & RR
A3: MAY TINH NHANH (sua o vang)
A4: Ty le thang (Win %) | B4: 0.5
A5: Ty le RR (1 : ?) | B5: 2
A6: Risk moi lenh (%) | B6: 0.01
A7: So lenh / thang | B7: ='Cai dat'!$B$7 -> 20
A8: Ky vong / lenh (R) = Win*RR-(1-Win) | B8: =B4*B5-(1-B4) -> 0.5
A9: Risk $ / lenh = So du*Risk% | B9: ='Cai dat'!$B$4*B6 -> 100
A10: Loi nhuan / lenh ($) = R*Risk$ | B10: =B8*B9 -> 50
A11: LOI NHUAN / THANG ($) | B11: =B10*B7 -> 1000
A12: LOI NHUAN / THANG (%) | B12: =B11/'Cai dat'!$B$4 -> 0.1
A15: A) KY VONG (R / lenh) = Win*RR-(1-Win)
A16: RR \ Win% | B16: 0.3 | C16: 0.4 | D16: 0.5 | E16: 0.6 | F16: 0.7
A17: 1 | B17: =B$16*$A17-(1-B$16) -> -0.4 | C17: =C$16*$A17-(1-C$16) -> -0.2 | D17: =D$16*$A17-(1-D$16) -> 0 | E17: =E$16*$A17-(1-E$16) -> 0.2 | F17: =F$16*$A17-(1-F$16) -> 0.4
A18: 1.5 | B18: =B$16*$A18-(1-B$16) -> -0.25 | C18: =C$16*$A18-(1-C$16) -> 0 | D18: =D$16*$A18-(1-D$16) -> 0.25 | E18: =E$16*$A18-(1-E$16) -> 0.5 | F18: =F$16*$A18-(1-F$16) -> 0.75
A19: 2 | B19: =B$16*$A19-(1-B$16) -> -0.1 | C19: =C$16*$A19-(1-C$16) -> 0.2 | D19: =D$16*$A19-(1-D$16) -> 0.5 | E19: =E$16*$A19-(1-E$16) -> 0.8 | F19: =F$16*$A19-(1-F$16) -> 1.1
A20: 2.5 | B20: =B$16*$A20-(1-B$16) -> 0.05 | C20: =C$16*$A20-(1-C$16) -> 0.4 | D20: =D$16*$A20-(1-D$16) -> 0.75 | E20: =E$16*$A20-(1-E$16) -> 1.1 | F20: =F$16*$A20-(1-F$16) -> 1.45
A21: 3 | B21: =B$16*$A21-(1-B$16) -> 0.2 | C21: =C$16*$A21-(1-C$16) -> 0.6 | D21: =D$16*$A21-(1-D$16) -> 1 | E21: =E$16*$A21-(1-E$16) -> 1.4 | F21: =F$16*$A21-(1-F$16) -> 1.8
A23: B) LOI NHUAN / THANG ($) @ Risk CAO (1%)
A24: RR \ Win% | B24: 0.3 | C24: 0.4 | D24: 0.5 | E24: 0.6 | F24: 0.7
A25: 1 | B25: =(B$24*$A25-(1-B$24))*'Cai dat'!$B$7*'Cai dat'!$B$9 -> -800 | C25: =(C$24*$A25-(1-C$24))*'Cai dat'!$B$7*'Cai dat'!$B$9 -> -400 | D25: =(D$24*$A25-(1-D$24))*'Cai dat'!$B$7*'Cai dat'!$B$9 -> 0 | E25: =(E$24*$A25-(1-E$24))*'Cai dat'!$B$7*'Cai dat'!$B$9 -> 400 | F25: =(F$24*$A25-(1-F$24))*'Cai dat'!$B$7*'Cai dat'!$B$9 -> 800
A26: 1.5 | B26: =(B$24*$A26-(1-B$24))*'Cai dat'!$B$7*'Cai dat'!$B$9 -> -500 | C26: =(C$24*$A26-(1-C$24))*'Cai dat'!$B$7*'Cai dat'!$B$9 -> 0 | D26: =(D$24*$A26-(1-D$24))*'Cai dat'!$B$7*'Cai dat'!$B$9 -> 500 | E26: =(E$24*$A26-(1-E$24))*'Cai dat'!$B$7*'Cai dat'!$B$9 -> 1000 | F26: =(F$24*$A26-(1-F$24))*'Cai dat'!$B$7*'Cai dat'!$B$9 -> 1500
A27: 2 | B27: =(B$24*$A27-(1-B$24))*'Cai dat'!$B$7*'Cai dat'!$B$9 -> -200 | C27: =(C$24*$A27-(1-C$24))*'Cai dat'!$B$7*'Cai dat'!$B$9 -> 400 | D27: =(D$24*$A27-(1-D$24))*'Cai dat'!$B$7*'Cai dat'!$B$9 -> 1000 | E27: =(E$24*$A27-(1-E$24))*'Cai dat'!$B$7*'Cai dat'!$B$9 -> 1600 | F27: =(F$24*$A27-(1-F$24))*'Cai dat'!$B$7*'Cai dat'!$B$9 -> 2200
A28: 2.5 | B28: =(B$24*$A28-(1-B$24))*'Cai dat'!$B$7*'Cai dat'!$B$9 -> 100 | C28: =(C$24*$A28-(1-C$24))*'Cai dat'!$B$7*'Cai dat'!$B$9 -> 800 | D28: =(D$24*$A28-(1-D$24))*'Cai dat'!$B$7*'Cai dat'!$B$9 -> 1500 | E28: =(E$24*$A28-(1-E$24))*'Cai dat'!$B$7*'Cai dat'!$B$9 -> 2200 | F28: =(F$24*$A28-(1-F$24))*'Cai dat'!$B$7*'Cai dat'!$B$9 -> 2900
A29: 3 | B29: =(B$24*$A29-(1-B$24))*'Cai dat'!$B$7*'Cai dat'!$B$9 -> 400 | C29: =(C$24*$A29-(1-C$24))*'Cai dat'!$B$7*'Cai dat'!$B$9 -> 1200 | D29: =(D$24*$A29-(1-D$24))*'Cai dat'!$B$7*'Cai dat'!$B$9 -> 2000 | E29: =(E$24*$A29-(1-E$24))*'Cai dat'!$B$7*'Cai dat'!$B$9 -> 2800 | F29: =(F$24*$A29-(1-F$24))*'Cai dat'!$B$7*'Cai dat'!$B$9 -> 3600
A31: C) LOI NHUAN / THANG ($) @ Risk THAP (0.5%)
A32: RR \ Win% | B32: 0.3 | C32: 0.4 | D32: 0.5 | E32: 0.6 | F32: 0.7
A33: 1 | B33: =(B$32*$A33-(1-B$32))*'Cai dat'!$B$7*'Cai dat'!$B$8 -> -400 | C33: =(C$32*$A33-(1-C$32))*'Cai dat'!$B$7*'Cai dat'!$B$8 -> -200 | D33: =(D$32*$A33-(1-D$32))*'Cai dat'!$B$7*'Cai dat'!$B$8 -> 0 | E33: =(E$32*$A33-(1-E$32))*'Cai dat'!$B$7*'Cai dat'!$B$8 -> 200 | F33: =(F$32*$A33-(1-F$32))*'Cai dat'!$B$7*'Cai dat'!$B$8 -> 400
A34: 1.5 | B34: =(B$32*$A34-(1-B$32))*'Cai dat'!$B$7*'Cai dat'!$B$8 -> -250 | C34: =(C$32*$A34-(1-C$32))*'Cai dat'!$B$7*'Cai dat'!$B$8 -> 0 | D34: =(D$32*$A34-(1-D$32))*'Cai dat'!$B$7*'Cai dat'!$B$8 -> 250 | E34: =(E$32*$A34-(1-E$32))*'Cai dat'!$B$7*'Cai dat'!$B$8 -> 500 | F34: =(F$32*$A34-(1-F$32))*'Cai dat'!$B$7*'Cai dat'!$B$8 -> 750
A35: 2 | B35: =(B$32*$A35-(1-B$32))*'Cai dat'!$B$7*'Cai dat'!$B$8 -> -100 | C35: =(C$32*$A35-(1-C$32))*'Cai dat'!$B$7*'Cai dat'!$B$8 -> 200 | D35: =(D$32*$A35-(1-D$32))*'Cai dat'!$B$7*'Cai dat'!$B$8 -> 500 | E35: =(E$32*$A35-(1-E$32))*'Cai dat'!$B$7*'Cai dat'!$B$8 -> 800 | F35: =(F$32*$A35-(1-F$32))*'Cai dat'!$B$7*'Cai dat'!$B$8 -> 1100
A36: 2.5 | B36: =(B$32*$A36-(1-B$32))*'Cai dat'!$B$7*'Cai dat'!$B$8 -> 50 | C36: =(C$32*$A36-(1-C$32))*'Cai dat'!$B$7*'Cai dat'!$B$8 -> 400 | D36: =(D$32*$A36-(1-D$32))*'Cai dat'!$B$7*'Cai dat'!$B$8 -> 750 | E36: =(E$32*$A36-(1-E$32))*'Cai dat'!$B$7*'Cai dat'!$B$8 -> 1100 | F36: =(F$32*$A36-(1-F$32))*'Cai dat'!$B$7*'Cai dat'!$B$8 -> 1450
A37: 3 | B37: =(B$32*$A37-(1-B$32))*'Cai dat'!$B$7*'Cai dat'!$B$8 -> 200 | C37: =(C$32*$A37-(1-C$32))*'Cai dat'!$B$7*'Cai dat'!$B$8 -> 600 | D37: =(D$32*$A37-(1-D$32))*'Cai dat'!$B$7*'Cai dat'!$B$8 -> 1000 | E37: =(E$32*$A37-(1-E$32))*'Cai dat'!$B$7*'Cai dat'!$B$8 -> 1400 | F37: =(F$32*$A37-(1-F$32))*'Cai dat'!$B$7*'Cai dat'!$B$8 -> 1800
A39: LUU Y: Day la KY VONG LY THUYET (fixed risk, 20 lenh/thang, chua tru spread/commission/slippage). Ket qua thuc te bien dong manh; chuoi thua lien tiep o 40% win co the vi pham gioi han lo cua FTMO. Xem sheet 'Rui ro FTMO'.

Sheet Rui ro FTMO
A1: RUI RO & GIOI HAN FTMO 10K
A3: Chi tieu | B3: Gia tri | C3: Ghi chu
A4: Muc tieu Phase 1 | B4: =0.1*'Cai dat'!$B$4 -> 1000 | C4: 10% = $1,000
A5: Muc tieu Phase 2 | B5: =0.05*'Cai dat'!$B$4 -> 500 | C5: 5% = $500
A6: Max daily loss | B6: =0.05*'Cai dat'!$B$4 -> 500 | C6: 5% tinh tren so du dau ngay (balance goc)
A7: Max total loss | B7: =0.1*'Cai dat'!$B$4 -> 1000 | C7: 10% tren balance goc
A8: So lenh thua LT toi da @1% cham daily-limit | B8: =ROUND(0.05/'Cai dat'!$B$6,0) -> 5 | C8: 5%/1% = 5 lenh thua/ngay la cham tran
A9: So lenh thua LT toi da @0.5% cham daily-limit | B9: =ROUND(0.05/'Cai dat'!$B$5,0) -> 10 | C9: 5%/0.5% = 10 lenh thua/ngay
A11: MENTOR NOTE: 1% risk cho ky vong cao hon nhung chi can 5 lenh thua lien tiep trong 1 ngay la vi pham daily loss limit cua FTMO. Voi win rate 40-50%, chuoi 5 thua HOAN TOAN co the xay ra. Giai doan foundation nen chon 0.5% de song sot qua variance, uu tien PROCESS hon OUTCOME.
